Workbook

Sheet Inputs
A1: Design inputs: change the blue cells
A2: Yellow = measurement still pending; replace when measured.
A3: Input | B3: Value | C3: Unit | D3: Source / status
A4: Release stroke at the drawbar, s_r | B4: 1.2 | C4: mm | D4: Assumed; replace with the release test (sheet section 5)
A5: Running gap, anvil to push pad | B5: 1 | C5: mm | D5: Design choice (anvil lift springs)
A6: Preload target, W | B6: 8.2 | C6: kN | D6: Hoss guidance 6.7-8.9 kN for TTS on small mills
A7: Collet push-out force, P | B7: 0.5 | C7: kN | D7: Assumed; first feel from the taper break test
A8: Washer flat load | B8: 14.2 | C8: kN | D8: Tormach 31319 not published: Solon 7H89 rate (23.6 kN/mm) x 0.6 mm h0
A9: Washer cone height, h0 | B9: 0.6 | C9: mm | D9: Tormach 31319, measured by viking45 (2.9 - 2.3 mm)
A10: Washer free height, l0 | B10: 2.9 | C10: mm | D10: Tormach 31319, measured by viking45; measure your own
A11: Release deflection limit | B11: 0.9 | C11: x h0 | D11: Keeps the washers off flat; Tormach runs them deep
A12: Washers fitted, n | B12: 8 | C12: pcs | D12: Locked: 8 x genuine Tormach 31319, as Tormach fits
A13: Washer mass each | B13: 11 | C13: g | D13: Calculated from 31319 dimensions
A14: Washer unit price | B14: 4.95 | C14: US$ | D14: Tormach 31319 listed price
A15: Washers to buy | B15: 16 | C15: pcs | D15: Two Tormach sets of 8: stack plus spares
... A21: Wedge angle | B21: 9.5 | C21: deg | D21: Design: tan 9.5 deg is about 1/6
A22: Wedge efficiency (rolling) | B22: 0.9 | D22: Assumed; rollers make friction small
A23: Collar axial holding, estimate | B23: 14 | C23: kN | D23: Estimate for two-piece collar, 3 x M8 12.9 per side
A24: Drawbar tip to spindle end face, H | B24: 250 | C24: mm | D24: From existing drawbar; confirm with new collet (sheet 3.5)
A25: Lower thread length, L1 | B25: 18 | C25: mm | D25: Collet thread depth + 3; placeholder (sheet 3.7)
A26: Collar shoulder thickness | B26: 6 | C26: mm | D26: Collar design
A27: Base thrust washer | B27: 3 | C27: mm | D27: Design
A28: Top thrust washer | B28: 4 | C28: mm | D28: Design
A29: Top thread length | B29: 28 | C29: mm | D29: Nut, jam nut, adjustment, pad
A30: Roller diameter | B30: 14 | C30: mm | D30: Dowel pins, ISO 8734, 58-62 HRC (purchased)
A31: Roller contact length (flat, between end chamfers) | B31: 36 | C31: mm | D31: 36 mm pins; measure the flat length and enter it
A32: Rollers per face | B32: 2 | C32: pcs | D32: Design
A33: Young's modulus, steel | B33: 210 | C33: GPa | D33: Standard value
A34: Poisson's ratio, steel | B34: 0.3 | D34: Standard value
A35: Track yield, hardened 4140 (wedge, anvil) | B35: 1380 | C35: MPa | D35: Atlas 4140 datasheet: yield above 1380 MPa when tempered 175-230 C
A36: Track yield, 4140 as supplied | B36: 740 | C36: MPa | D36: Atlas 4140 datasheet: condition U, 0.2% proof 740 MPa min (bar to 180 mm)
A37: Line-contact first yield, p0 / yield | B37: 1.79 | D37: Johnson, Contact Mechanics (1985), von Mises; from memory
A38: Wedge thickness at the trailing end | B38: 23.5 | C38: mm | D38: Wedge drawing
A39: Hole centre below the wedge top | B39: 11.75 | C39: mm | D39: Wedge drawing (centred)
A40: Rod-joint thread, major diameter | B40: 14 | C40: mm | D40: M14 x 1.5 (rod re-measured 29 Oct 2026; SMC JA40-14-150)
A41: Thread depth in the wedge | B41: 14 | C41: mm | D41: Wedge drawing
A42: Tap drill diameter | B42: 12.5 | C42: mm | D42: M14 x 1.5 tap drill
A43: Drill depth | B43: 18 | C43: mm | D43: Wedge drawing
A44: Roof wear plate thickness | B44: 5 | C44: mm | D44: O1 40 x 5 ground flat stock (ordered 29 Oct 2026)
A45: Hard stop beyond the release stroke | B45: 0.3 | C45: mm | D45: Design: stop at s_r + 0.3

Sheet Design
A1: Design results for the current inputs
A2: All formulas; washer force taken as linear, flat load / h0 (Solon 7H89 at low cone height).
A3: Result | B3: Value | C3: Unit | D3: Check
A4: Mechanical advantage, 1/tan(angle) | B4: =1/TAN(RADIANS(Inputs!$B$21)) -> 5.9757644
A5: Washer rate, per washer | B5: =Inputs!$B$8/Inputs!$B$9 -> 23.666667 | C5: kN/mm
A6: Preload deflection per washer | B6: =Inputs!$B$6/$B$5 -> 0.34647887 | C6: mm
A7: Preload deflection | B7: =$B$6/Inputs!$B$9 -> 0.57746479 | C7: x h0
A8: Washers needed for the limit at this stroke | B8: =ROUNDUP(Inputs!$B$4/((Inputs!$B$11-$B$7)*Inputs!$B$9),0) -> 7 | C8: pcs
A9: Release deflection per washer | B9: =$B$6+Inputs!$B$4/Inputs!$B$12 -> 0.49647887 | C9: mm
A10: Release deflection | B10: =$B$9/Inputs!$B$9 -> 0.82746479 | C10: x h0 | D10: =IF($B$10<=Inputs!$B$11,"OK","Add washers") -> OK
A11: Stack force at release | B11: =MIN($B$5*$B$9,Inputs!$B$8) -> 11.75 | C11: kN
A12: Required at drawbar, incl. P | B12: =$B$11+Inputs!$B$7 -> 12.25 | C12: kN
A13: Bore area | B13: =PI()*Inputs!$B$16^2/4 -> 5026.5482 | C13: mm2
A14: Cylinder push at regulator | B14: =$B$13*Inputs!$B$19/10/1000 -> 2.5132741 | C14: kN
A15: Drawbar force available | B15: =$B$14*$B$4*Inputs!$B$22 -> 13.516861 | C15: kN
A16: Release margin | B16: =$B$15/$B$12-1 -> 0.10341719 | D16: =IF($B$16>=0.1,"OK",IF($B$16>=0,"Thin","Will not release")) -> OK
A17: Expected release pressure | B17: =$B$12*1000/($B$13*$B$4*Inputs!$B$22)*10 -> 4.5313777 | C17: bar | D17: =IF($B$17<=Inputs!$B$19-0.5,"OK","Thin: under 0.5 bar headroom") -> Thin: under 0.5 bar headroom
A18: Wedge (cylinder) travel needed | B18: =$B$4*(Inputs!$B$4+Inputs!$B$5) -> 13.146682 | C18: mm | D18: =IF($B$18<=Inputs!$B$17-3,"OK","Short of stroke") -> OK
A19: Largest stroke the cylinder covers | B19: =(Inputs!$B$17-3)/$B$4-Inputs!$B$5 -> 2.6815374 | C19: mm
A20: Stack free length | B20: =Inputs!$B$12*Inputs!$B$10 -> 23.2 | C20: mm
A21: Stack preloaded length (set to this) | B21: =Inputs!$B$12*(Inputs!$B$10-$B$6) -> 20.428169 | C21: mm
A22: Top thrust washer top above spindle face | B22: =Inputs!$B$26+Inputs!$B$27+$B$21+Inputs!$B$28 -> 33.428169 | C22: mm
A23: Drawbar overall length | B23: =Inputs!$B$24+$B$22+Inputs!$B$29 -> 311.42817 | C23: mm
A24: Guide section length (11.2 mm) | B24: =3+$B$22 -> 36.428169 | C24: mm
A25: Body length (11.0 mm) | B25: =Inputs!$B$24-Inputs!$B$25-3 -> 229 | C25: mm
A26: Cylinder push at full supply | B26: =$B$13*Inputs!$B$20/10/1000 -> 3.1164599 | C26: kN
A27: Stuck-collet collar load at regulator | B27: =$B$15-Inputs!$B$6 -> 5.3168605 | C27: kN
A28: Collar margin at regulator | B28: =Inputs!$B$23/$B$27 -> 2.6331328 | C28: x | D28: =IF($B$28>=2,"OK",IF($B$28>=1.5,"Thin","Low")) -> OK
A29: Stuck-collet collar load at full supply | B29: =$B$26*$B$4*Inputs!$B$22-Inputs!$B$6 -> 8.5609071 | C29: kN
A30: Collar margin at full supply | B30: =Inputs!$B$23/$B$29 -> 1.6353407 | C30: x
A31: Wedge travel to the hard stop | B31: =$B$4*(Inputs!$B$4+Inputs!$B$45+Inputs!$B$5) -> 14.939411 | C31: mm | D31: =IF($B$31<=Inputs!$B$17-3,"OK","Short of stroke") -> OK
A32: Cage travel at the hard stop (half the wedge) | B32: =$B$31/2 -> 7.4697055 | C32: mm
A33: Drawbar force at full supply | B33: =$B$26*$B$4*Inputs!$B$22 -> 16.760907 | C33: kN
A34: Normal load on each roller face, full supply | B34: =$B$33/COS(RADIANS(Inputs!$B$21)) -> 16.993969 | C34: kN
A35: Contact modulus E* | B35: =Inputs!$B$33*1000/(2*(1-Inputs!$B$34^2)) -> 115384.62 | C35: MPa
A36: Hertz peak, rollers sharing, at regulator | B36: =SQRT($B$15/COS(RADIANS(Inputs!$B$21))*1000/Inputs!$B$32*$B$35/(PI()*Inputs!$B$31*Inputs!$B$30/2)) -> 999.35622 | C36: MPa
A37: Hertz peak, rollers sharing, full supply | B37: =SQRT($B$34*1000/Inputs!$B$32*$B$35/(PI()*Inputs!$B$31*Inputs!$B$30/2)) -> 1112.836 | C37: MPa | D37: =IF($B$37<=Inputs!$B$37*Inputs!$B$36,"OK even unhardened",IF($B$37<=Inputs!$B$37*Inputs!$B$35,"OK hardened","Yields")) -> OK even unhardened
A38: Hertz peak, one roller takes all, full supply | B38: =SQRT($B$34*1000*$B$35/(PI()*Inputs!$B$31*Inputs!$B$30/2)) -> 1573.7877 | C38: MPa | D38: =IF($B$38<=Inputs!$B$37*Inputs!$B$36,"OK even unhardened",IF($B$38<=Inputs!$B$37*Inputs!$B$35,"OK hardened only","Yields: grind faces parallel")) -> OK hardened only
A39: First-yield contact pressure, hardened 4140 | B39: =Inputs!$B$37*Inputs!$B$35 -> 2470.2 | C39: MPa
A40: Margin, one roller takes all, hardened | B40: =$B$39/$B$38 -> 1.569589 | C40: x | D40: =IF($B$40>=1.3,"OK","Thin") -> OK
...

Sheet Stroke scenarios
A1: Performance of the fitted stack by release stroke
A2: Uses the washer count fitted on Inputs (8). Release beyond the deflection limit or a negative margin means: fit a genuine Tormach collet or raise the regulator.
A4: Release stroke (mm) | B4: Washers fitted | C4: Release deflection (x h0) | D4: Release force (kN) | E4: Required at drawbar (kN) | F4: Margin at regulator | G4: Expected release pressure (bar) | H4: Preloaded stack (mm) | I4: Drawbar length (mm) | J4: Cylinder travel (mm) | K4: Within deflection limit? | L4: Margin at 5.5 bar
A5: 0.6 | B5: =Inputs!$B$12 -> 8 | C5: =(Design!$B$6+A5/B5)/Inputs!$B$9 -> 0.70246479 | D5: =MIN(Design!$B$5*(Design!$B$6+A5/B5),Inputs!$B$8) -> 9.975 | E5: =D5+Inputs!$B$7 -> 10.475 | F5: =Design!$B$15/E5-1 -> 0.29039242 | G5: =E5*1000/(Design!$B$13*Design!$B$4*Inputs!$B$22)*10 -> 3.8747903 | H5: =B5*(Inputs!$B$10-Design!$B$6) -> 20.428169 | I5: =Inputs!$B$24+Inputs!$B$26+Inputs!$B$27+H5+Inputs!$B$28+Inputs!$B$29 -> 311.42817 | J5: =Design!$B$4*(A5+Inputs!$B$5) -> 9.561223 | K5: =IF(C5<=Inputs!$B$11,"Yes","No") -> Yes | L5: =Design!$B$13*5.5/10/1000*Design!$B$4*Inputs!$B$22/E5-1 -> 0.41943166
A6: 0.8 | B6: =Inputs!$B$12 -> 8 | C6: =(Design!$B$6+A6/B6)/Inputs!$B$9 -> 0.74413146 | D6: =MIN(Design!$B$5*(Design!$B$6+A6/B6),Inputs!$B$8) -> 10.566667 | E6: =D6+Inputs!$B$7 -> 11.066667 | F6: =Design!$B$15/E6-1 -> 0.22140306 | G6: =E6*1000/(Design!$B$13*Design!$B$4*Inputs!$B$22)*10 -> 4.0936527 | H6: =B6*(Inputs!$B$10-Design!$B$6) -> 20.428169 | I6: =Inputs!$B$24+Inputs!$B$26+Inputs!$B$27+H6+Inputs!$B$28+Inputs!$B$29 -> 311.42817 | J6: =Design!$B$4*(A6+Inputs!$B$5) -> 10.756376 | K6: =IF(C6<=Inputs!$B$11,"Yes","No") -> Yes | L6: =Design!$B$13*5.5/10/1000*Design!$B$4*Inputs!$B$22/E6-1 -> 0.34354337
A7: 1 | B7: =Inputs!$B$12 -> 8 | C7: =(Design!$B$6+A7/B7)/Inputs!$B$9 -> 0.78579812 | D7: =MIN(Design!$B$5*(Design!$B$6+A7/B7),Inputs!$B$8) -> 11.158333 | E7: =D7+Inputs!$B$7 -> 11.658333 | F7: =Design!$B$15/E7-1 -> 0.1594162 | G7: =E7*1000/(Design!$B$13*Design!$B$4*Inputs!$B$22)*10 -> 4.3125152 | H7: =B7*(Inputs!$B$10-Design!$B$6) -> 20.428169 | I7: =Inputs!$B$24+Inputs!$B$26+Inputs!$B$27+H7+Inputs!$B$28+Inputs!$B$29 -> 311.42817 | J7: =Design!$B$4*(A7+Inputs!$B$5) -> 11.951529 | K7: =IF(C7<=Inputs!$B$11,"Yes","No") -> Yes | L7: =Design!$B$13*5.5/10/1000*Design!$B$4*Inputs!$B$22/E7-1 -> 0.27535782
A8: 1.2 | B8: =Inputs!$B$12 -> 8 | C8: =(Design!$B$6+A8/B8)/Inputs!$B$9 -> 0.82746479 | D8: =MIN(Design!$B$5*(Design!$B$6+A8/B8),Inputs!$B$8) -> 11.75 | E8: =D8+Inputs!$B$7 -> 12.25 | F8: =Design!$B$15/E8-1 -> 0.10341719 | G8: =E8*1000/(Design!$B$13*Design!$B$4*Inputs!$B$22)*10 -> 4.5313777 | H8: =B8*(Inputs!$B$10-Design!$B$6) -> 20.428169 | I8: =Inputs!$B$24+Inputs!$B$26+Inputs!$B$27+H8+Inputs!$B$28+Inputs!$B$29 -> 311.42817 | J8: =Design!$B$4*(A8+Inputs!$B$5) -> 13.146682 | K8: =IF(C8<=Inputs!$B$11,"Yes","No") -> Yes | L8: =Design!$B$13*5.5/10/1000*Design!$B$4*Inputs!$B$22/E8-1 -> 0.21375891
A9: 1.4 | B9: =Inputs!$B$12 -> 8 | C9: =(Design!$B$6+A9/B9)/Inputs!$B$9 -> 0.86913146 | D9: =MIN(Design!$B$5*(Design!$B$6+A9/B9),Inputs!$B$8) -> 12.341667 | E9: =D9+Inputs!$B$7 -> 12.841667 | F9: =Design!$B$15/E9-1 -> 0.052578368 | G9: =E9*1000/(Design!$B$13*Design!$B$4*Inputs!$B$22)*10 -> 4.7502401 | H9: =B9*(Inputs!$B$10-Design!$B$6) -> 20.428169 | I9: =Inputs!$B$24+Inputs!$B$26+Inputs!$B$27+H9+Inputs!$B$28+Inputs!$B$29 -> 311.42817 | J9: =Design!$B$4*(A9+Inputs!$B$5) -> 14.341834 | K9: =IF(C9<=Inputs!$B$11,"Yes","No") -> Yes | L9: =Design!$B$13*5.5/10/1000*Design!$B$4*Inputs!$B$22/E9-1 -> 0.15783621
A10: 1.6 | B10: =Inputs!$B$12 -> 8 | C10: =(Design!$B$6+A10/B10)/Inputs!$B$9 -> 0.91079812 | D10: =MIN(Design!$B$5*(Design!$B$6+A10/B10),Inputs!$B$8) -> 12.933333 | E10: =D10+Inputs!$B$7 -> 13.433333 | F10: =Design!$B$15/E10-1 -> 0.0062179068 | G10: =E10*1000/(Design!$B$13*Design!$B$4*Inputs!$B$22)*10 -> 4.9691026 | H10: =B10*(Inputs!$B$10-Design!$B$6) -> 20.428169 | I10: =Inputs!$B$24+Inputs!$B$26+Inputs!$B$27+H10+Inputs!$B$28+Inputs!$B$29 -> 311.42817 | J10: =Design!$B$4*(A10+Inputs!$B$5) -> 15.536987 | K10: =IF(C10<=Inputs!$B$11,"Yes","No") -> No | L10: =Design!$B$13*5.5/10/1000*Design!$B$4*Inputs!$B$22/E10-1 -> 0.1068397
A11: 1.8 | B11: =Inputs!$B$12 -> 8 | C11: =(Design!$B$6+A11/B11)/Inputs!$B$9 -> 0.95246479 | D11: =MIN(Design!$B$5*(Design!$B$6+A11/B11),Inputs!$B$8) -> 13.525 | E11: =D11+Inputs!$B$7 -> 14.025 | F11: =Design!$B$15/E11-1 -> -0.036230977 | G11: =E11*1000/(Design!$B$13*Design!$B$4*Inputs!$B$22)*10 -> 5.187965 | H11: =B11*(Inputs!$B$10-Design!$B$6) -> 20.428169 | I11: =Inputs!$B$24+Inputs!$B$26+Inputs!$B$27+H11+Inputs!$B$28+Inputs!$B$29 -> 311.42817 | J11: =Design!$B$4*(A11+Inputs!$B$5) -> 16.73214 | K11: =IF(C11<=Inputs!$B$11,"Yes","No") -> No | L11: =Design!$B$13*5.5/10/1000*Design!$B$4*Inputs!$B$22/E11-1 -> 0.060145925
A12: 2 | B12: =Inputs!$B$12 -> 8 | C12: =(Design!$B$6+A12/B12)/Inputs!$B$9 -> 0.99413146 | D12: =MIN(Design!$B$5*(Design!$B$6+A12/B12),Inputs!$B$8) -> 14.116667 | E12: =D12+Inputs!$B$7 -> 14.616667 | F12: =Design!$B$15/E12-1 -> -0.075243292 | G12: =E12*1000/(Design!$B$13*Design!$B$4*Inputs!$B$22)*10 -> 5.4068275 | H12: =B12*(Inputs!$B$10-Design!$B$6) -> 20.428169 | I12: =Inputs!$B$24+Inputs!$B$26+Inputs!$B$27+H12+Inputs!$B$28+Inputs!$B$29 -> 311.42817 | J12: =Design!$B$4*(A12+Inputs!$B$5) -> 17.927293 | K12: =IF(C12<=Inputs!$B$11,"Yes","No") -> No | L12: =Design!$B$13*5.5/10/1000*Design!$B$4*Inputs!$B$22/E12-1 -> 0.017232379

Sheet Wedge and pressure
A1: Wedge angle and regulator options
A2: Release margin uses the required drawbar force from Design; collar load is the stuck-collet case.
A4: Drawbar force available (kN)
A5: Wedge angle (deg) \ bar | B5: 4.5 | C5: 5 | D5: 5.5 | E5: 6.2
A6: 8.5 | B6: =Design!$B$13*B$5/10/1000/TAN(RADIANS($A6))*Inputs!$B$22 -> 13.621535 | C6: =Design!$B$13*C$5/10/1000/TAN(RADIANS($A6))*Inputs!$B$22 -> 15.135039 | D6: =Design!$B$13*D$5/10/1000/TAN(RADIANS($A6))*Inputs!$B$22 -> 16.648543 | E6: =Design!$B$13*E$5/10/1000/TAN(RADIANS($A6))*Inputs!$B$22 -> 18.767448
A7: 9.5 | B7: =Design!$B$13*B$5/10/1000/TAN(RADIANS($A7))*Inputs!$B$22 -> 12.165174 | C7: =Design!$B$13*C$5/10/1000/TAN(RADIANS($A7))*Inputs!$B$22 -> 13.516861 | D7: =Design!$B$13*D$5/10/1000/TAN(RADIANS($A7))*Inputs!$B$22 -> 14.868547 | E7: =Design!$B$13*E$5/10/1000/TAN(RADIANS($A7))*Inputs!$B$22 -> 16.760907
A8: 10.5 | B8: =Design!$B$13*B$5/10/1000/TAN(RADIANS($A8))*Inputs!$B$22 -> 10.983935 | C8: =Design!$B$13*C$5/10/1000/TAN(RADIANS($A8))*Inputs!$B$22 -> 12.204372 | D8: =Design!$B$13*D$5/10/1000/TAN(RADIANS($A8))*Inputs!$B$22 -> 13.42481 | E8: =Design!$B$13*E$5/10/1000/TAN(RADIANS($A8))*Inputs!$B$22 -> 15.133422
A10: Release margin over required drawbar force
A11: Wedge angle (deg) \ bar | B11: 4.5 | C11: 5 | D11: 5.5 | E11: 6.2
A12: 8.5 | B12: =Design!$B$13*B$11/10/1000/TAN(RADIANS($A12))*Inputs!$B$22/Design!$B$12-1 -> 0.11196204 | C12: =Design!$B$13*C$11/10/1000/TAN(RADIANS($A12))*Inputs!$B$22/Design!$B$12-1 -> 0.23551337 | D12: =Design!$B$13*D$11/10/1000/TAN(RADIANS($A12))*Inputs!$B$22/Design!$B$12-1 -> 0.35906471 | E12: =Design!$B$13*E$11/10/1000/TAN(RADIANS($A12))*Inputs!$B$22/Design!$B$12-1 -> 0.53203658
A13: 9.5 | B13: =Design!$B$13*B$11/10/1000/TAN(RADIANS($A13))*Inputs!$B$22/Design!$B$12-1 -> -0.0069245312 | C13: =Design!$B$13*C$11/10/1000/TAN(RADIANS($A13))*Inputs!$B$22/Design!$B$12-1 -> 0.10341719 | D13: =Design!$B$13*D$11/10/1000/TAN(RADIANS($A13))*Inputs!$B$22/Design!$B$12-1 -> 0.21375891 | E13: =Design!$B$13*E$11/10/1000/TAN(RADIANS($A13))*Inputs!$B$22/Design!$B$12-1 -> 0.36823731
A14: 10.5 | B14: =Design!$B$13*B$11/10/1000/TAN(RADIANS($A14))*Inputs!$B$22/Design!$B$12-1 -> -0.10335224 | C14: =Design!$B$13*C$11/10/1000/TAN(RADIANS($A14))*Inputs!$B$22/Design!$B$12-1 -> -0.0037247082 | D14: =Design!$B$13*D$11/10/1000/TAN(RADIANS($A14))*Inputs!$B$22/Design!$B$12-1 -> 0.095902821 | E14: =Design!$B$13*E$11/10/1000/TAN(RADIANS($A14))*Inputs!$B$22/Design!$B$12-1 -> 0.23538136
A16: Stuck-collet collar load (kN)
A17: Wedge angle (deg) \ bar | B17: 4.5 | C17: 5 | D17: 5.5 | E17: 6.2
A18: 8.5 | B18: =Design!$B$13*B$17/10/1000/TAN(RADIANS($A18))*Inputs!$B$22-Inputs!$B$6 -> 5.421535 | C18: =Design!$B$13*C$17/10/1000/TAN(RADIANS($A18))*Inputs!$B$22-Inputs!$B$6 -> 6.9350388 | D18: =Design!$B$13*D$17/10/1000/TAN(RADIANS($A18))*Inputs!$B$22-Inputs!$B$6 -> 8.4485427 | E18: =Design!$B$13*E$17/10/1000/TAN(RADIANS($A18))*Inputs!$B$22-Inputs!$B$6 -> 10.567448
A19: 9.5 | B19: =Design!$B$13*B$17/10/1000/TAN(RADIANS($A19))*Inputs!$B$22-Inputs!$B$6 -> 3.9651745 | C19: =Design!$B$13*C$17/10/1000/TAN(RADIANS($A19))*Inputs!$B$22-Inputs!$B$6 -> 5.3168605 | D19: =Design!$B$13*D$17/10/1000/TAN(RADIANS($A19))*Inputs!$B$22-Inputs!$B$6 -> 6.6685466 | E19: =Design!$B$13*E$17/10/1000/TAN(RADIANS($A19))*Inputs!$B$22-Inputs!$B$6 -> 8.5609071
A20: 10.5 | B20: =Design!$B$13*B$17/10/1000/TAN(RADIANS($A20))*Inputs!$B$22-Inputs!$B$6 -> 2.7839351 | C20: =Design!$B$13*C$17/10/1000/TAN(RADIANS($A20))*Inputs!$B$22-Inputs!$B$6 -> 4.0043723 | D20: =Design!$B$13*D$17/10/1000/TAN(RADIANS($A20))*Inputs!$B$22-Inputs!$B$6 -> 5.2248096 | E20: =Design!$B$13*E$17/10/1000/TAN(RADIANS($A20))*Inputs!$B$22-Inputs!$B$6 -> 6.9334217
A22: Collar margin (estimated holding / load)
A23: Wedge angle (deg) \ bar | B23: 4.5 | C23: 5 | D23: 5.5 | E23: 6.2
A24: 8.5 | B24: =Inputs!$B$23/(Design!$B$13*B$23/10/1000/TAN(RADIANS($A24))*Inputs!$B$22-Inputs!$B$6) -> 2.5822945 | C24: =Inputs!$B$23/(Design!$B$13*C$23/10/1000/TAN(RADIANS($A24))*Inputs!$B$22-Inputs!$B$6) -> 2.0187342 | D24: =Inputs!$B$23/(Design!$B$13*D$23/10/1000/TAN(RADIANS($A24))*Inputs!$B$22-Inputs!$B$6) -> 1.6570905 | E24: =Inputs!$B$23/(Design!$B$13*E$23/10/1000/TAN(RADIANS($A24))*Inputs!$B$22-Inputs!$B$6) -> 1.3248232
A25: 9.5 | B25: =Inputs!$B$23/(Design!$B$13*B$23/10/1000/TAN(RADIANS($A25))*Inputs!$B$22-Inputs!$B$6) -> 3.53074 | C25: =Inputs!$B$23/(Design!$B$13*C$23/10/1000/TAN(RADIANS($A25))*Inputs!$B$22-Inputs!$B$6) -> 2.6331328 | D25: =Inputs!$B$23/(Design!$B$13*D$23/10/1000/TAN(RADIANS($A25))*Inputs!$B$22-Inputs!$B$6) -> 2.099408 | E25: =Inputs!$B$23/(Design!$B$13*E$23/10/1000/TAN(RADIANS($A25))*Inputs!$B$22-Inputs!$B$6) -> 1.6353407
A26: 10.5 | B26: =Inputs!$B$23/(Design!$B$13*B$23/10/1000/TAN(RADIANS($A26))*Inputs!$B$22-Inputs!$B$6) -> 5.0288529 | C26: =Inputs!$B$23/(Design!$B$13*C$23/10/1000/TAN(RADIANS($A26))*Inputs!$B$22-Inputs!$B$6) -> 3.4961784 | D26: =Inputs!$B$23/(Design!$B$13*D$23/10/1000/TAN(RADIANS($A26))*Inputs!$B$22-Inputs!$B$6) -> 2.6795235 | E26: =Inputs!$B$23/(Design!$B$13*E$23/10/1000/TAN(RADIANS($A26))*Inputs!$B$22-Inputs!$B$6) -> 2.019205
A28: Wedge travel needed for the current stroke (mm), of 25
A29: Wedge angle (deg) \ bar | B29: 4.5 | C29: 5 | D29: 5.5 | E29: 6.2
A30: 8.5 | B30: =1/TAN(RADIANS($A30))*(Inputs!$B$4+Inputs!$B$5) -> 14.720544 | C30: =1/TAN(RADIANS($A30))*(Inputs!$B$4+Inputs!$B$5) -> 14.720544 | D30: =1/TAN(RADIANS($A30))*(Inputs!$B$4+Inputs!$B$5) -> 14.720544 | E30: =1/TAN(RADIANS($A30))*(Inputs!$B$4+Inputs!$B$5) -> 14.720544
A31: 9.5 | B31: =1/TAN(RADIANS($A31))*(Inputs!$B$4+Inputs!$B$5) -> 13.146682 | C31: =1/TAN(RADIANS($A31))*(Inputs!$B$4+Inputs!$B$5) -> 13.146682 | D31: =1/TAN(RADIANS($A31))*(Inputs!$B$4+Inputs!$B$5) -> 13.146682 | E31: =1/TAN(RADIANS($A31))*(Inputs!$B$4+Inputs!$B$5) -> 13.146682
A32: 10.5 | B32: =1/TAN(RADIANS($A32))*(Inputs!$B$4+Inputs!$B$5) -> 11.870138 | C32: =1/TAN(RADIANS($A32))*(Inputs!$B$4+Inputs!$B$5) -> 11.870138 | D32: =1/TAN(RADIANS($A32))*(Inputs!$B$4+Inputs!$B$5) -> 11.870138 | E32: =1/TAN(RADIANS($A32))*(Inputs!$B$4+Inputs!$B$5) -> 11.870138
A35: Current design: 9.5 deg (about 6:1) at 5.0 bar. Aim for release margin of at least 10% and collar margin of at least 2.

Sheet Notes
A1: Notes and sources
A2: Washers: 8 x genuine Tormach 31319 (30.2 x 11.4 x 2.3 mm, US$4.95, sets of 8). Load not published; rate taken from the same-size Solon 7H89177 (15.1 kN flat at 0.64 mm). https://www.solonmfg.com/7h89177
A3: Tormach 31319 product page: https://tormach.com/power-drawbar-spring-washer-31319.html ; free height 2.9 mm measured by viking45 (CNCArena).
A4: Tormach PCNC 1100 power drawbar uses 8 x 31319. https://tormach.com/media/asset/t/d/td10039_pcnc1100_powerdrawbar_1119a.pdf
A5: Washer force is modelled as linear (flat load / h0); real Belleville curves are slightly regressive, so forces near flat are a little high here.
A6: Collar holding (14 kN) is an engineering estimate, not a published rating; verify with the witness line.
A7: Hertz line contact: p = sqrt(F E* / (pi L R)), E* = E / (2(1 - nu^2)); F per roller = normal face load / rollers per face. Enter the measured flat length of the pins as L.
A8: Wedge geometry: drawbar force = cylinder force / tan(angle) x efficiency; anvil forward thrust = drawbar force x tan(angle), taken by the rear thrust bar (bronze faced).
A9: Stack heights exclude the nut and pad; drawbar length = H + shoulder + base washer + preloaded stack + top washer + top thread.
A10: Contact check (29 Oct 2026): first yield of a line contact at p0 = 1.79 x yield (von Mises; Johnson 1985, from memory). Wedge and anvil are 4140 hardened and tempered at about 200 C (Atlas: yield above 1380 MPa). https://atlassteels.com.au/wp-content/uploads/2021/09/Through-Hardening-Low-Alloy-Steel-Bar-4140-Grade-Data-Sheet-10-09-21-1.pdf
A11: Floating joint SMC JA40-14-150, 4400 N max tension/compression. https://static.smc.eu/pdf/JA-A_EU.pdf . Wedge M14 x 1.5 hole kept to 14 deep thread, 18 deep drill so the 9.5 deg slope leaves at least about 2.4 mm wall; the JA nut bears on the end face.
A12: Yellow inputs are pending measurements or unpublished data: release stroke, push-out force, washer rate and heights, rod diameter, H and L1.
A13: If release needs more stroke than the 8-washer stack allows, fit a genuine Tormach collet before adding washers (design decision 28 Oct 2026).
